[2025-01-21T15:06:12.892+0000] {taskinstance.py:1956} INFO - Dependencies all met for dep_context=non-requeueable deps ti=<TaskInstance: 11_notificatons_dag.task1 scheduled__2025-01-21T15:03:10+00:00 [queued]>
[2025-01-21T15:06:12.989+0000] {taskinstance.py:1956} INFO - Dependencies all met for dep_context=requeueable deps ti=<TaskInstance: 11_notificatons_dag.task1 scheduled__2025-01-21T15:03:10+00:00 [queued]>
[2025-01-21T15:06:13.000+0000] {taskinstance.py:2170} INFO - Starting attempt 4 of 6
[2025-01-21T15:06:13.204+0000] {taskinstance.py:2191} INFO - Executing <Task(PythonOperator): task1> on 2025-01-21 15:03:10+00:00
[2025-01-21T15:06:13.256+0000] {standard_task_runner.py:60} INFO - Started process 1266 to run task
[2025-01-21T15:06:13.255+0000] {standard_task_runner.py:87} INFO - Running: ['***', 'tasks', 'run', '11_notificatons_dag', 'task1', 'scheduled__2025-01-21T15:03:10+00:00', '--job-id', '30', '--raw', '--subdir', 'DAGS_FOLDER/11_notifications_dag.py', '--cfg-path', '/tmp/tmpambgmxfe']
[2025-01-21T15:06:13.271+0000] {standard_task_runner.py:88} INFO - Job 30: Subtask task1
[2025-01-21T15:06:13.300+0000] {warnings.py:109} WARNING - /home/***/.local/lib/python3.8/site-packages/***/settings.py:194: DeprecationWarning: The sql_alchemy_conn option in [core] has been moved to the sql_alchemy_conn option in [database] - the old setting has been used, but please update your config.
  SQL_ALCHEMY_CONN = conf.get("database", "SQL_ALCHEMY_CONN")

[2025-01-21T15:06:13.450+0000] {task_command.py:423} INFO - Running <TaskInstance: 11_notificatons_dag.task1 scheduled__2025-01-21T15:03:10+00:00 [running]> on host d3a2c9f62df6
[2025-01-21T15:06:13.974+0000] {taskinstance.py:2480} INFO - Exporting env vars: AIRFLOW_CTX_DAG_EMAIL='hzhang.davis@gmail.com' AIRFLOW_CTX_DAG_OWNER='***' AIRFLOW_CTX_DAG_ID='11_notificatons_dag' AIRFLOW_CTX_TASK_ID='task1' AIRFLOW_CTX_EXECUTION_DATE='2025-01-21T15:03:10+00:00' AIRFLOW_CTX_TRY_NUMBER='4' AIRFLOW_CTX_DAG_RUN_ID='scheduled__2025-01-21T15:03:10+00:00'
[2025-01-21T15:06:13.984+0000] {taskinstance.py:2698} ERROR - Task failed with exception
Traceback (most recent call last):
  File "/home/airflow/.local/lib/python3.8/site-packages/airflow/models/taskinstance.py", line 433, in _execute_task
    result = execute_callable(context=context, **execute_callable_kwargs)
  File "/home/airflow/.local/lib/python3.8/site-packages/airflow/operators/python.py", line 199, in execute
    return_value = self.execute_callable()
  File "/home/airflow/.local/lib/python3.8/site-packages/airflow/operators/python.py", line 216, in execute_callable
    return self.python_callable(*self.op_args, **self.op_kwargs)
  File "/opt/airflow/dags/11_notifications_dag.py", line 9, in failed_task
    raise Exception('This task did not work!')
Exception: This task did not work!
[2025-01-21T15:06:14.031+0000] {taskinstance.py:1138} INFO - Marking task as UP_FOR_RETRY. dag_id=11_notificatons_dag, task_id=task1, execution_date=20250121T150310, start_date=20250121T150612, end_date=20250121T150614
[2025-01-21T15:06:14.167+0000] {warnings.py:109} WARNING - /home/***/.local/lib/python3.8/site-packages/***/utils/email.py:154: RemovedInAirflow3Warning: Fetching SMTP credentials from configuration variables will be deprecated in a future release. Please set credentials using a connection instead.
  send_mime_email(e_from=mail_from, e_to=recipients, mime_msg=msg, conn_id=conn_id, dryrun=dryrun)

[2025-01-21T15:06:14.174+0000] {email.py:270} INFO - Email alerting: attempt 1
[2025-01-21T15:06:14.350+0000] {email.py:270} INFO - Email alerting: attempt 1
[2025-01-21T15:06:14.497+0000] {taskinstance.py:826} ERROR - Failed to send email to: ['hzhang.davis@gmail.com']
Traceback (most recent call last):
  File "/home/airflow/.local/lib/python3.8/site-packages/airflow/models/taskinstance.py", line 2334, in _run_raw_task
    self._execute_task_with_callbacks(context, test_mode, session=session)
  File "/home/airflow/.local/lib/python3.8/site-packages/airflow/models/taskinstance.py", line 2499, in _execute_task_with_callbacks
    result = self._execute_task(context, task_orig)
  File "/home/airflow/.local/lib/python3.8/site-packages/airflow/models/taskinstance.py", line 2516, in _execute_task
    return _execute_task(self, context, task_orig)
  File "/home/airflow/.local/lib/python3.8/site-packages/airflow/models/taskinstance.py", line 433, in _execute_task
    result = execute_callable(context=context, **execute_callable_kwargs)
  File "/home/airflow/.local/lib/python3.8/site-packages/airflow/operators/python.py", line 199, in execute
    return_value = self.execute_callable()
  File "/home/airflow/.local/lib/python3.8/site-packages/airflow/operators/python.py", line 216, in execute_callable
    return self.python_callable(*self.op_args, **self.op_kwargs)
  File "/opt/airflow/dags/11_notifications_dag.py", line 9, in failed_task
    raise Exception('This task did not work!')
Exception: This task did not work!

During handling of the above exception, another exception occurred:

Traceback (most recent call last):
  File "/home/airflow/.local/lib/python3.8/site-packages/airflow/models/taskinstance.py", line 1000, in _email_alert
    send_email(task.email, subject, html_content)
  File "/home/airflow/.local/lib/python3.8/site-packages/airflow/utils/email.py", line 80, in send_email
    return backend(
  File "/home/airflow/.local/lib/python3.8/site-packages/airflow/utils/email.py", line 154, in send_email_smtp
    send_mime_email(e_from=mail_from, e_to=recipients, mime_msg=msg, conn_id=conn_id, dryrun=dryrun)
  File "/home/airflow/.local/lib/python3.8/site-packages/airflow/utils/email.py", line 280, in send_mime_email
    smtp_conn.login(smtp_user, smtp_password)
  File "/usr/local/lib/python3.8/smtplib.py", line 748, in login
    raise last_exception
  File "/usr/local/lib/python3.8/smtplib.py", line 737, in login
    (code, resp) = self.auth(
  File "/usr/local/lib/python3.8/smtplib.py", line 660, in auth
    raise SMTPAuthenticationError(code, resp)
smtplib.SMTPAuthenticationError: (535, b'5.7.8 Username and Password not accepted. For more information, go to\n5.7.8  https://support.google.com/mail/?p=BadCredentials ffacd0b85a97d-38bf322b51bsm13814885f8f.60 - gsmtp')

During handling of the above exception, another exception occurred:

Traceback (most recent call last):
  File "/home/airflow/.local/lib/python3.8/site-packages/airflow/models/taskinstance.py", line 824, in _handle_failure
    task_instance.email_alert(error, failure_context["task"])
  File "/home/airflow/.local/lib/python3.8/site-packages/airflow/models/taskinstance.py", line 2946, in email_alert
    _email_alert(task_instance=self, exception=exception, task=task)
  File "/home/airflow/.local/lib/python3.8/site-packages/airflow/models/taskinstance.py", line 1002, in _email_alert
    send_email(task.email, subject, html_content_err)
  File "/home/airflow/.local/lib/python3.8/site-packages/airflow/utils/email.py", line 80, in send_email
    return backend(
  File "/home/airflow/.local/lib/python3.8/site-packages/airflow/utils/email.py", line 154, in send_email_smtp
    send_mime_email(e_from=mail_from, e_to=recipients, mime_msg=msg, conn_id=conn_id, dryrun=dryrun)
  File "/home/airflow/.local/lib/python3.8/site-packages/airflow/utils/email.py", line 280, in send_mime_email
    smtp_conn.login(smtp_user, smtp_password)
  File "/usr/local/lib/python3.8/smtplib.py", line 748, in login
    raise last_exception
  File "/usr/local/lib/python3.8/smtplib.py", line 737, in login
    (code, resp) = self.auth(
  File "/usr/local/lib/python3.8/smtplib.py", line 660, in auth
    raise SMTPAuthenticationError(code, resp)
smtplib.SMTPAuthenticationError: (535, b'5.7.8 Username and Password not accepted. For more information, go to\n5.7.8  https://support.google.com/mail/?p=BadCredentials ffacd0b85a97d-38bf32755f0sm13700172f8f.76 - gsmtp')
[2025-01-21T15:06:14.587+0000] {standard_task_runner.py:107} ERROR - Failed to execute job 30 for task task1 (This task did not work!; 1266)
[2025-01-21T15:06:14.678+0000] {local_task_job_runner.py:234} INFO - Task exited with return code 1
[2025-01-21T15:06:14.826+0000] {taskinstance.py:3280} INFO - 0 downstream tasks scheduled from follow-on schedule check
