[2025-01-22T10:24:00.725+0000] {taskinstance.py:1956} INFO - Dependencies all met for dep_context=non-requeueable deps ti=<TaskInstance: 22_sensor_dag.print_file_content manual__2025-01-22T10:23:55.407230+00:00 [queued]>
[2025-01-22T10:24:00.767+0000] {taskinstance.py:1956} INFO - Dependencies all met for dep_context=requeueable deps ti=<TaskInstance: 22_sensor_dag.print_file_content manual__2025-01-22T10:23:55.407230+00:00 [queued]>
[2025-01-22T10:24:00.768+0000] {taskinstance.py:2170} INFO - Starting attempt 1 of 1
[2025-01-22T10:24:00.834+0000] {taskinstance.py:2191} INFO - Executing <Task(BashOperator): print_file_content> on 2025-01-22 10:23:55.407230+00:00
[2025-01-22T10:24:00.857+0000] {standard_task_runner.py:60} INFO - Started process 1354 to run task
[2025-01-22T10:24:00.881+0000] {standard_task_runner.py:87} INFO - Running: ['***', 'tasks', 'run', '22_sensor_dag', 'print_file_content', 'manual__2025-01-22T10:23:55.407230+00:00', '--job-id', '65', '--raw', '--subdir', 'DAGS_FOLDER/22_FileSensor.py', '--cfg-path', '/tmp/tmph7wmon3h']
[2025-01-22T10:24:00.905+0000] {standard_task_runner.py:88} INFO - Job 65: Subtask print_file_content
[2025-01-22T10:24:00.960+0000] {warnings.py:109} WARNING - /home/***/.local/lib/python3.8/site-packages/***/settings.py:194: DeprecationWarning: The sql_alchemy_conn option in [core] has been moved to the sql_alchemy_conn option in [database] - the old setting has been used, but please update your config.
  SQL_ALCHEMY_CONN = conf.get("database", "SQL_ALCHEMY_CONN")

[2025-01-22T10:24:01.099+0000] {task_command.py:423} INFO - Running <TaskInstance: 22_sensor_dag.print_file_content manual__2025-01-22T10:23:55.407230+00:00 [running]> on host d3a2c9f62df6
[2025-01-22T10:24:01.229+0000] {taskinstance.py:2480} INFO - Exporting env vars: AIRFLOW_CTX_DAG_OWNER='***' AIRFLOW_CTX_DAG_ID='22_sensor_dag' AIRFLOW_CTX_TASK_ID='print_file_content' AIRFLOW_CTX_EXECUTION_DATE='2025-01-22T10:23:55.407230+00:00' AIRFLOW_CTX_TRY_NUMBER='1' AIRFLOW_CTX_DAG_RUN_ID='manual__2025-01-22T10:23:55.407230+00:00'
[2025-01-22T10:24:01.231+0000] {subprocess.py:63} INFO - Tmp dir root location: /tmp
[2025-01-22T10:24:01.232+0000] {subprocess.py:75} INFO - Running command: ['/usr/bin/bash', '-c', 'cat /tmp/my_file.txt']
[2025-01-22T10:24:01.252+0000] {subprocess.py:86} INFO - Output:
[2025-01-22T10:24:01.262+0000] {subprocess.py:93} INFO - cat: /tmp/my_file.txt: No such file or directory
[2025-01-22T10:24:01.264+0000] {subprocess.py:97} INFO - Command exited with return code 1
[2025-01-22T10:24:01.297+0000] {taskinstance.py:2698} ERROR - Task failed with exception
Traceback (most recent call last):
  File "/home/airflow/.local/lib/python3.8/site-packages/airflow/models/taskinstance.py", line 433, in _execute_task
    result = execute_callable(context=context, **execute_callable_kwargs)
  File "/home/airflow/.local/lib/python3.8/site-packages/airflow/operators/bash.py", line 212, in execute
    raise AirflowException(
airflow.exceptions.AirflowException: Bash command failed. The command returned a non-zero exit code 1.
[2025-01-22T10:24:01.305+0000] {taskinstance.py:1138} INFO - Marking task as FAILED. dag_id=22_sensor_dag, task_id=print_file_content, execution_date=20250122T102355, start_date=20250122T102400, end_date=20250122T102401
[2025-01-22T10:24:01.330+0000] {standard_task_runner.py:107} ERROR - Failed to execute job 65 for task print_file_content (Bash command failed. The command returned a non-zero exit code 1.; 1354)
[2025-01-22T10:24:01.380+0000] {local_task_job_runner.py:234} INFO - Task exited with return code 1
[2025-01-22T10:24:01.453+0000] {taskinstance.py:3280} INFO - 0 downstream tasks scheduled from follow-on schedule check
